---
title: L'istruzione 'Throw' non può omettere l'operando all'esterno di un'istruzione 'Catch' o all'interno di un'istruzione 'Finally'
ms.date: 07/20/2015
f1_keywords:
- vbc30666
- bc30666
helpviewer_keywords:
- BC30666
ms.assetid: a208a6ea-0e36-4bf1-8984-4de1a0e38a2a
ms.openlocfilehash: 17e7817c608e9c3513e0320b62f42410613f33b0
ms.sourcegitcommit: 558d78d2a68acd4c95ef23231c8b4e4c7bac3902
ms.translationtype: MT
ms.contentlocale: it-IT
ms.lasthandoff: 04/09/2019
ms.locfileid: "59302491"
---
# <a name="throw-statement-cannot-omit-operand-outside-a-catch-statement-or-inside-a-finally-statement"></a><span data-ttu-id="b7ca9-102">L'istruzione 'Throw' non può omettere l'operando all'esterno di un'istruzione 'Catch' o all'interno di un'istruzione 'Finally'</span><span class="sxs-lookup"><span data-stu-id="b7ca9-102">'Throw' statement cannot omit operand outside a 'Catch' statement or inside a 'Finally' statement</span></span>
`Throw` <span data-ttu-id="b7ca9-103">di fuori dell'istruzione `Catch` devono fornire il nome di un oggetto eccezione.</span><span class="sxs-lookup"><span data-stu-id="b7ca9-103">statements outside of `Catch` statement must supply the name of an exception object.</span></span>  
  
 <span data-ttu-id="b7ca9-104">**ID errore:** BC30666</span><span class="sxs-lookup"><span data-stu-id="b7ca9-104">**Error ID:** BC30666</span></span>  
  
## <a name="to-correct-this-error"></a><span data-ttu-id="b7ca9-105">Per correggere l'errore</span><span class="sxs-lookup"><span data-stu-id="b7ca9-105">To correct this error</span></span>  
  
1. <span data-ttu-id="b7ca9-106">Specificare il nome di un oggetto eccezione derivato da `System.Exception`.</span><span class="sxs-lookup"><span data-stu-id="b7ca9-106">Specify the name of an exception object derived from `System.Exception`.</span></span>  
  
2. <span data-ttu-id="b7ca9-107">Ristrutturare il codice in modo che l'istruzione `Throw` si trovi in un blocco `Catch` .</span><span class="sxs-lookup"><span data-stu-id="b7ca9-107">Restructure your code so that the `Throw` statement is inside a `Catch` block.</span></span>  
  
## <a name="see-also"></a><span data-ttu-id="b7ca9-108">Vedere anche</span><span class="sxs-lookup"><span data-stu-id="b7ca9-108">See also</span></span>

- [<span data-ttu-id="b7ca9-109">Istruzione Throw</span><span class="sxs-lookup"><span data-stu-id="b7ca9-109">Throw Statement</span></span>](../../visual-basic/language-reference/statements/throw-statement.md)
- [<span data-ttu-id="b7ca9-110">Istruzione Try...Catch...Finally</span><span class="sxs-lookup"><span data-stu-id="b7ca9-110">Try...Catch...Finally Statement</span></span>](../../visual-basic/language-reference/statements/try-catch-finally-statement.md)
- <xref:System.Exception?displayProperty=nameWithType>
- [<span data-ttu-id="b7ca9-111">Gestione e generazione di eccezioni in .NET</span><span class="sxs-lookup"><span data-stu-id="b7ca9-111">Handling and throwing exceptions in .NET</span></span>](../../standard/exceptions/index.md)
